2019-06-01 13:10:12,292 (4043/MainThread) litecli.main ERROR - sql: '.tabls', error: OperationalError('near ".": syntax error',)
2019-06-01 13:10:12,294 (4043/MainThread) litecli.main ERROR - traceback: 'Traceback (most recent call last):\n  File "/home/bryan/.local/pipx/venvs/litecli/lib64/python3.6/site-packages/litecli/sqlexecute.py", line 116, in run\n    for result in special.execute(cur, sql):\n  File "/home/bryan/.local/pipx/venvs/litecli/lib64/python3.6/site-packages/litecli/packages/special/main.py", line 104, in execute\n    raise CommandNotFound\nlitecli.packages.special.main.CommandNotFound\n\nDuring handling of the above exception, another exception occurred:\n\nTraceback (most recent call last):\n  File "/home/bryan/.local/pipx/venvs/litecli/lib64/python3.6/site-packages/litecli/main.py", line 440, in one_iteration\n    for title, cur, headers, status in res:\n  File "/home/bryan/.local/pipx/venvs/litecli/lib64/python3.6/site-packages/litecli/sqlexecute.py", line 120, in run\n    cur.execute(sql)\nsqlite3.OperationalError: near ".": syntax error\n'
2019-06-01 13:11:48,420 (4043/MainThread) litecli.main ERROR - sql: 'select url from History;', error: DatabaseError('database disk image is malformed',)
2019-06-01 13:11:48,421 (4043/MainThread) litecli.main ERROR - traceback: 'Traceback (most recent call last):\n  File "/home/bryan/.local/pipx/venvs/litecli/lib64/python3.6/site-packages/litecli/sqlexecute.py", line 116, in run\n    for result in special.execute(cur, sql):\n  File "/home/bryan/.local/pipx/venvs/litecli/lib64/python3.6/site-packages/litecli/packages/special/main.py", line 104, in execute\n    raise CommandNotFound\nlitecli.packages.special.main.CommandNotFound\n\nDuring handling of the above exception, another exception occurred:\n\nTraceback (most recent call last):\n  File "/home/bryan/.local/pipx/venvs/litecli/lib64/python3.6/site-packages/litecli/main.py", line 440, in one_iteration\n    for title, cur, headers, status in res:\n  File "/home/bryan/.local/pipx/venvs/litecli/lib64/python3.6/site-packages/litecli/sqlexecute.py", line 121, in run\n    yield self.get_result(cur)\n  File "/home/bryan/.local/pipx/venvs/litecli/lib64/python3.6/site-packages/litecli/sqlexecute.py", line 132, in get_result\n    cursor = list(cursor)\nsqlite3.DatabaseError: database disk image is malformed\n'
2019-06-01 13:11:52,123 (4043/MainThread) litecli.main ERROR - sql: 'select url from History;', error: DatabaseError('database disk image is malformed',)
2019-06-01 13:11:52,123 (4043/MainThread) litecli.main ERROR - traceback: 'Traceback (most recent call last):\n  File "/home/bryan/.local/pipx/venvs/litecli/lib64/python3.6/site-packages/litecli/sqlexecute.py", line 116, in run\n    for result in special.execute(cur, sql):\n  File "/home/bryan/.local/pipx/venvs/litecli/lib64/python3.6/site-packages/litecli/packages/special/main.py", line 104, in execute\n    raise CommandNotFound\nlitecli.packages.special.main.CommandNotFound\n\nDuring handling of the above exception, another exception occurred:\n\nTraceback (most recent call last):\n  File "/home/bryan/.local/pipx/venvs/litecli/lib64/python3.6/site-packages/litecli/main.py", line 440, in one_iteration\n    for title, cur, headers, status in res:\n  File "/home/bryan/.local/pipx/venvs/litecli/lib64/python3.6/site-packages/litecli/sqlexecute.py", line 121, in run\n    yield self.get_result(cur)\n  File "/home/bryan/.local/pipx/venvs/litecli/lib64/python3.6/site-packages/litecli/sqlexecute.py", line 132, in get_result\n    cursor = list(cursor)\nsqlite3.DatabaseError: database disk image is malformed\n'
2019-06-02 16:40:22,784 (14411/MainThread) litecli.main ERROR - sql: '.table', error: OperationalError('near ".": syntax error',)
2019-06-02 16:40:22,786 (14411/MainThread) litecli.main ERROR - traceback: 'Traceback (most recent call last):\n  File "/home/bryan/.local/pipx/venvs/litecli/lib64/python3.6/site-packages/litecli/sqlexecute.py", line 116, in run\n    for result in special.execute(cur, sql):\n  File "/home/bryan/.local/pipx/venvs/litecli/lib64/python3.6/site-packages/litecli/packages/special/main.py", line 104, in execute\n    raise CommandNotFound\nlitecli.packages.special.main.CommandNotFound\n\nDuring handling of the above exception, another exception occurred:\n\nTraceback (most recent call last):\n  File "/home/bryan/.local/pipx/venvs/litecli/lib64/python3.6/site-packages/litecli/main.py", line 440, in one_iteration\n    for title, cur, headers, status in res:\n  File "/home/bryan/.local/pipx/venvs/litecli/lib64/python3.6/site-packages/litecli/sqlexecute.py", line 120, in run\n    cur.execute(sql)\nsqlite3.OperationalError: near ".": syntax error\n'
2019-06-02 16:40:27,952 (14411/MainThread) litecli.main ERROR - sql: '.table `NoteTable`', error: OperationalError('near ".": syntax error',)
2019-06-02 16:40:27,952 (14411/MainThread) litecli.main ERROR - traceback: 'Traceback (most recent call last):\n  File "/home/bryan/.local/pipx/venvs/litecli/lib64/python3.6/site-packages/litecli/sqlexecute.py", line 116, in run\n    for result in special.execute(cur, sql):\n  File "/home/bryan/.local/pipx/venvs/litecli/lib64/python3.6/site-packages/litecli/packages/special/main.py", line 104, in execute\n    raise CommandNotFound\nlitecli.packages.special.main.CommandNotFound\n\nDuring handling of the above exception, another exception occurred:\n\nTraceback (most recent call last):\n  File "/home/bryan/.local/pipx/venvs/litecli/lib64/python3.6/site-packages/litecli/main.py", line 440, in one_iteration\n    for title, cur, headers, status in res:\n  File "/home/bryan/.local/pipx/venvs/litecli/lib64/python3.6/site-packages/litecli/sqlexecute.py", line 120, in run\n    cur.execute(sql)\nsqlite3.OperationalError: near ".": syntax error\n'
2019-06-02 16:43:09,938 (14411/MainThread) litecli.main ERROR - sql: '.quit', error: OperationalError('near ".": syntax error',)
2019-06-02 16:43:09,939 (14411/MainThread) litecli.main ERROR - traceback: 'Traceback (most recent call last):\n  File "/home/bryan/.local/pipx/venvs/litecli/lib64/python3.6/site-packages/litecli/sqlexecute.py", line 116, in run\n    for result in special.execute(cur, sql):\n  File "/home/bryan/.local/pipx/venvs/litecli/lib64/python3.6/site-packages/litecli/packages/special/main.py", line 104, in execute\n    raise CommandNotFound\nlitecli.packages.special.main.CommandNotFound\n\nDuring handling of the above exception, another exception occurred:\n\nTraceback (most recent call last):\n  File "/home/bryan/.local/pipx/venvs/litecli/lib64/python3.6/site-packages/litecli/main.py", line 440, in one_iteration\n    for title, cur, headers, status in res:\n  File "/home/bryan/.local/pipx/venvs/litecli/lib64/python3.6/site-packages/litecli/sqlexecute.py", line 120, in run\n    cur.execute(sql)\nsqlite3.OperationalError: near ".": syntax error\n'
2019-06-03 16:02:49,487 (8925/MainThread) litecli.main ERROR - sql: '.quit', error: OperationalError('near ".": syntax error',)
2019-06-03 16:02:49,488 (8925/MainThread) litecli.main ERROR - traceback: 'Traceback (most recent call last):\n  File "/home/bryan/.local/pipx/venvs/litecli/lib64/python3.6/site-packages/litecli/sqlexecute.py", line 116, in run\n    for result in special.execute(cur, sql):\n  File "/home/bryan/.local/pipx/venvs/litecli/lib64/python3.6/site-packages/litecli/packages/special/main.py", line 104, in execute\n    raise CommandNotFound\nlitecli.packages.special.main.CommandNotFound\n\nDuring handling of the above exception, another exception occurred:\n\nTraceback (most recent call last):\n  File "/home/bryan/.local/pipx/venvs/litecli/lib64/python3.6/site-packages/litecli/main.py", line 440, in one_iteration\n    for title, cur, headers, status in res:\n  File "/home/bryan/.local/pipx/venvs/litecli/lib64/python3.6/site-packages/litecli/sqlexecute.py", line 120, in run\n    cur.execute(sql)\nsqlite3.OperationalError: near ".": syntax error\n'
2019-06-23 18:39:40,445 (9705/MainThread) litecli.main ERROR - sql: 'q', error: OperationalError('near "q": syntax error',)
2019-06-23 18:39:40,446 (9705/MainThread) litecli.main ERROR - traceback: 'Traceback (most recent call last):\n  File "/home/bryan/.local/pipx/venvs/litecli/lib64/python3.6/site-packages/litecli/sqlexecute.py", line 116, in run\n    for result in special.execute(cur, sql):\n  File "/home/bryan/.local/pipx/venvs/litecli/lib64/python3.6/site-packages/litecli/packages/special/main.py", line 104, in execute\n    raise CommandNotFound\nlitecli.packages.special.main.CommandNotFound\n\nDuring handling of the above exception, another exception occurred:\n\nTraceback (most recent call last):\n  File "/home/bryan/.local/pipx/venvs/litecli/lib64/python3.6/site-packages/litecli/main.py", line 440, in one_iteration\n    for title, cur, headers, status in res:\n  File "/home/bryan/.local/pipx/venvs/litecli/lib64/python3.6/site-packages/litecli/sqlexecute.py", line 120, in run\n    cur.execute(sql)\nsqlite3.OperationalError: near "q": syntax error\n'
2020-04-29 13:51:33,208 (23862/MainThread) litecli.main ERROR - sql: 'ls', error: OperationalError('near "ls": syntax error',)
2020-04-29 13:51:33,209 (23862/MainThread) litecli.main ERROR - traceback: 'Traceback (most recent call last):\n  File "/home/bryan/.local/pipx/venvs/litecli/lib64/python3.6/site-packages/litecli/sqlexecute.py", line 121, in run\n    for result in special.execute(cur, sql):\n  File "/home/bryan/.local/pipx/venvs/litecli/lib64/python3.6/site-packages/litecli/packages/special/main.py", line 109, in execute\n    raise CommandNotFound\nlitecli.packages.special.main.CommandNotFound\n\nDuring handling of the above exception, another exception occurred:\n\nTraceback (most recent call last):\n  File "/home/bryan/.local/pipx/venvs/litecli/lib64/python3.6/site-packages/litecli/main.py", line 441, in one_iteration\n    for title, cur, headers, status in res:\n  File "/home/bryan/.local/pipx/venvs/litecli/lib64/python3.6/site-packages/litecli/sqlexecute.py", line 125, in run\n    cur.execute(sql)\nsqlite3.OperationalError: near "ls": syntax error\n'
2020-04-29 13:51:34,813 (23862/MainThread) litecli.main ERROR - sql: 'q', error: OperationalError('near "q": syntax error',)
2020-04-29 13:51:34,813 (23862/MainThread) litecli.main ERROR - traceback: 'Traceback (most recent call last):\n  File "/home/bryan/.local/pipx/venvs/litecli/lib64/python3.6/site-packages/litecli/sqlexecute.py", line 121, in run\n    for result in special.execute(cur, sql):\n  File "/home/bryan/.local/pipx/venvs/litecli/lib64/python3.6/site-packages/litecli/packages/special/main.py", line 109, in execute\n    raise CommandNotFound\nlitecli.packages.special.main.CommandNotFound\n\nDuring handling of the above exception, another exception occurred:\n\nTraceback (most recent call last):\n  File "/home/bryan/.local/pipx/venvs/litecli/lib64/python3.6/site-packages/litecli/main.py", line 441, in one_iteration\n    for title, cur, headers, status in res:\n  File "/home/bryan/.local/pipx/venvs/litecli/lib64/python3.6/site-packages/litecli/sqlexecute.py", line 125, in run\n    cur.execute(sql)\nsqlite3.OperationalError: near "q": syntax error\n'
2020-04-29 13:51:35,999 (23862/MainThread) litecli.main ERROR - sql: '.q', error: OperationalError('near ".": syntax error',)
2020-04-29 13:51:36,000 (23862/MainThread) litecli.main ERROR - traceback: 'Traceback (most recent call last):\n  File "/home/bryan/.local/pipx/venvs/litecli/lib64/python3.6/site-packages/litecli/sqlexecute.py", line 121, in run\n    for result in special.execute(cur, sql):\n  File "/home/bryan/.local/pipx/venvs/litecli/lib64/python3.6/site-packages/litecli/packages/special/main.py", line 109, in execute\n    raise CommandNotFound\nlitecli.packages.special.main.CommandNotFound\n\nDuring handling of the above exception, another exception occurred:\n\nTraceback (most recent call last):\n  File "/home/bryan/.local/pipx/venvs/litecli/lib64/python3.6/site-packages/litecli/main.py", line 441, in one_iteration\n    for title, cur, headers, status in res:\n  File "/home/bryan/.local/pipx/venvs/litecli/lib64/python3.6/site-packages/litecli/sqlexecute.py", line 125, in run\n    cur.execute(sql)\nsqlite3.OperationalError: near ".": syntax error\n'
2020-04-29 21:34:40,327 (28765/MainThread) litecli.main ERROR - sql: 'll', error: OperationalError('near "ll": syntax error',)
2020-04-29 21:34:40,328 (28765/MainThread) litecli.main ERROR - traceback: 'Traceback (most recent call last):\n  File "/home/bryan/.local/pipx/venvs/litecli/lib64/python3.6/site-packages/litecli/sqlexecute.py", line 121, in run\n    for result in special.execute(cur, sql):\n  File "/home/bryan/.local/pipx/venvs/litecli/lib64/python3.6/site-packages/litecli/packages/special/main.py", line 109, in execute\n    raise CommandNotFound\nlitecli.packages.special.main.CommandNotFound\n\nDuring handling of the above exception, another exception occurred:\n\nTraceback (most recent call last):\n  File "/home/bryan/.local/pipx/venvs/litecli/lib64/python3.6/site-packages/litecli/main.py", line 441, in one_iteration\n    for title, cur, headers, status in res:\n  File "/home/bryan/.local/pipx/venvs/litecli/lib64/python3.6/site-packages/litecli/sqlexecute.py", line 125, in run\n    cur.execute(sql)\nsqlite3.OperationalError: near "ll": syntax error\n'
2020-04-30 12:12:27,739 (24975/MainThread) litecli.main ERROR - sql: '\\f', error: OperationalError('Not connected to database.',)
2020-04-30 12:12:27,742 (24975/MainThread) litecli.main ERROR - traceback: 'Traceback (most recent call last):\n  File "/home/bryan/.local/pipx/venvs/litecli/lib64/python3.6/site-packages/litecli/main.py", line 441, in one_iteration\n    for title, cur, headers, status in res:\n  File "/home/bryan/.local/pipx/venvs/litecli/lib64/python3.6/site-packages/litecli/sqlexecute.py", line 114, in run\n    raise OperationalError("Not connected to database.")\nsqlite3.OperationalError: Not connected to database.\n'
2020-04-30 12:15:43,636 (27486/MainThread) litecli.main ERROR - sql: 'll', error: OperationalError('near "ll": syntax error',)
2020-04-30 12:15:43,639 (27486/MainThread) litecli.main ERROR - traceback: 'Traceback (most recent call last):\n  File "/home/bryan/.local/pipx/venvs/litecli/lib64/python3.6/site-packages/litecli/sqlexecute.py", line 121, in run\n    for result in special.execute(cur, sql):\n  File "/home/bryan/.local/pipx/venvs/litecli/lib64/python3.6/site-packages/litecli/packages/special/main.py", line 109, in execute\n    raise CommandNotFound\nlitecli.packages.special.main.CommandNotFound\n\nDuring handling of the above exception, another exception occurred:\n\nTraceback (most recent call last):\n  File "/home/bryan/.local/pipx/venvs/litecli/lib64/python3.6/site-packages/litecli/main.py", line 441, in one_iteration\n    for title, cur, headers, status in res:\n  File "/home/bryan/.local/pipx/venvs/litecli/lib64/python3.6/site-packages/litecli/sqlexecute.py", line 125, in run\n    cur.execute(sql)\nsqlite3.OperationalError: near "ll": syntax error\n'
2020-04-30 14:00:08,358 (26179/MainThread) litecli.main ERROR - sql: 'score', error: OperationalError('near "score": syntax error',)
2020-04-30 14:00:08,359 (26179/MainThread) litecli.main ERROR - traceback: 'Traceback (most recent call last):\n  File "/home/bryan/.local/pipx/venvs/litecli/lib64/python3.6/site-packages/litecli/sqlexecute.py", line 121, in run\n    for result in special.execute(cur, sql):\n  File "/home/bryan/.local/pipx/venvs/litecli/lib64/python3.6/site-packages/litecli/packages/special/main.py", line 109, in execute\n    raise CommandNotFound\nlitecli.packages.special.main.CommandNotFound\n\nDuring handling of the above exception, another exception occurred:\n\nTraceback (most recent call last):\n  File "/home/bryan/.local/pipx/venvs/litecli/lib64/python3.6/site-packages/litecli/main.py", line 441, in one_iteration\n    for title, cur, headers, status in res:\n  File "/home/bryan/.local/pipx/venvs/litecli/lib64/python3.6/site-packages/litecli/sqlexecute.py", line 125, in run\n    cur.execute(sql)\nsqlite3.OperationalError: near "score": syntax error\n'
2020-04-30 14:01:59,792 (28425/MainThread) litecli.main ERROR - sql: 'score', error: OperationalError('near "score": syntax error',)
2020-04-30 14:01:59,793 (28425/MainThread) litecli.main ERROR - traceback: 'Traceback (most recent call last):\n  File "/home/bryan/.local/pipx/venvs/litecli/lib64/python3.6/site-packages/litecli/sqlexecute.py", line 121, in run\n    for result in special.execute(cur, sql):\n  File "/home/bryan/.local/pipx/venvs/litecli/lib64/python3.6/site-packages/litecli/packages/special/main.py", line 109, in execute\n    raise CommandNotFound\nlitecli.packages.special.main.CommandNotFound\n\nDuring handling of the above exception, another exception occurred:\n\nTraceback (most recent call last):\n  File "/home/bryan/.local/pipx/venvs/litecli/lib64/python3.6/site-packages/litecli/main.py", line 441, in one_iteration\n    for title, cur, headers, status in res:\n  File "/home/bryan/.local/pipx/venvs/litecli/lib64/python3.6/site-packages/litecli/sqlexecute.py", line 125, in run\n    cur.execute(sql)\nsqlite3.OperationalError: near "score": syntax error\n'
2020-04-30 14:02:23,475 (28675/MainThread) litecli.main ERROR - sql: 'score', error: OperationalError('near "score": syntax error',)
2020-04-30 14:02:23,475 (28675/MainThread) litecli.main ERROR - traceback: 'Traceback (most recent call last):\n  File "/home/bryan/.local/pipx/venvs/litecli/lib64/python3.6/site-packages/litecli/sqlexecute.py", line 121, in run\n    for result in special.execute(cur, sql):\n  File "/home/bryan/.local/pipx/venvs/litecli/lib64/python3.6/site-packages/litecli/packages/special/main.py", line 109, in execute\n    raise CommandNotFound\nlitecli.packages.special.main.CommandNotFound\n\nDuring handling of the above exception, another exception occurred:\n\nTraceback (most recent call last):\n  File "/home/bryan/.local/pipx/venvs/litecli/lib64/python3.6/site-packages/litecli/main.py", line 441, in one_iteration\n    for title, cur, headers, status in res:\n  File "/home/bryan/.local/pipx/venvs/litecli/lib64/python3.6/site-packages/litecli/sqlexecute.py", line 125, in run\n    cur.execute(sql)\nsqlite3.OperationalError: near "score": syntax error\n'
2020-04-30 14:32:34,849 (18911/MainThread) litecli.main ERROR - sql: 'score', error: OperationalError('near "score": syntax error',)
2020-04-30 14:32:34,850 (18911/MainThread) litecli.main ERROR - traceback: 'Traceback (most recent call last):\n  File "/home/bryan/.local/pipx/venvs/litecli/lib64/python3.6/site-packages/litecli/sqlexecute.py", line 121, in run\n    for result in special.execute(cur, sql):\n  File "/home/bryan/.local/pipx/venvs/litecli/lib64/python3.6/site-packages/litecli/packages/special/main.py", line 109, in execute\n    raise CommandNotFound\nlitecli.packages.special.main.CommandNotFound\n\nDuring handling of the above exception, another exception occurred:\n\nTraceback (most recent call last):\n  File "/home/bryan/.local/pipx/venvs/litecli/lib64/python3.6/site-packages/litecli/main.py", line 441, in one_iteration\n    for title, cur, headers, status in res:\n  File "/home/bryan/.local/pipx/venvs/litecli/lib64/python3.6/site-packages/litecli/sqlexecute.py", line 125, in run\n    cur.execute(sql)\nsqlite3.OperationalError: near "score": syntax error\n'
2020-04-30 14:35:47,814 (20798/MainThread) litecli.main ERROR - sql: 'select round(score, 2), search_location, title, company, post_date, url from jobs where score > 15 order desc by score \\G', error: OperationalError('near "desc": syntax error',)
2020-04-30 14:35:47,814 (20798/MainThread) litecli.main ERROR - traceback: 'Traceback (most recent call last):\n  File "/home/bryan/.local/pipx/venvs/litecli/lib64/python3.6/site-packages/litecli/sqlexecute.py", line 121, in run\n    for result in special.execute(cur, sql):\n  File "/home/bryan/.local/pipx/venvs/litecli/lib64/python3.6/site-packages/litecli/packages/special/main.py", line 109, in execute\n    raise CommandNotFound\nlitecli.packages.special.main.CommandNotFound\n\nDuring handling of the above exception, another exception occurred:\n\nTraceback (most recent call last):\n  File "/home/bryan/.local/pipx/venvs/litecli/lib64/python3.6/site-packages/litecli/main.py", line 441, in one_iteration\n    for title, cur, headers, status in res:\n  File "/home/bryan/.local/pipx/venvs/litecli/lib64/python3.6/site-packages/litecli/sqlexecute.py", line 125, in run\n    cur.execute(sql)\nsqlite3.OperationalError: near "desc": syntax error\n'
2020-04-30 14:42:55,394 (31916/MainThread) litecli.main ERROR - sql: '\\f v', error: OperationalError('unrecognized token: "\\"',)
2020-04-30 14:42:55,395 (31916/MainThread) litecli.main ERROR - traceback: 'Traceback (most recent call last):\n  File "/home/bryan/.local/pipx/venvs/litecli/lib64/python3.6/site-packages/litecli/main.py", line 441, in one_iteration\n    for title, cur, headers, status in res:\n  File "/home/bryan/.local/pipx/venvs/litecli/lib64/python3.6/site-packages/litecli/sqlexecute.py", line 121, in run\n    for result in special.execute(cur, sql):\n  File "/home/bryan/.local/pipx/venvs/litecli/lib64/python3.6/site-packages/litecli/packages/special/iocommands.py", line 210, in execute_favorite_query\n    cur.execute(sql)\nsqlite3.OperationalError: unrecognized token: "\\"\n'
2020-04-30 14:43:34,658 (31916/MainThread) litecli.main ERROR - sql: '\\f v \\G', error: OperationalError('unrecognized token: "\\"',)
2020-04-30 14:43:34,659 (31916/MainThread) litecli.main ERROR - traceback: 'Traceback (most recent call last):\n  File "/home/bryan/.local/pipx/venvs/litecli/lib64/python3.6/site-packages/litecli/main.py", line 441, in one_iteration\n    for title, cur, headers, status in res:\n  File "/home/bryan/.local/pipx/venvs/litecli/lib64/python3.6/site-packages/litecli/sqlexecute.py", line 121, in run\n    for result in special.execute(cur, sql):\n  File "/home/bryan/.local/pipx/venvs/litecli/lib64/python3.6/site-packages/litecli/packages/special/iocommands.py", line 210, in execute_favorite_query\n    cur.execute(sql)\nsqlite3.OperationalError: unrecognized token: "\\"\n'
2020-04-30 14:43:38,512 (31916/MainThread) litecli.main ERROR - sql: '\\f v', error: OperationalError('unrecognized token: "\\"',)
2020-04-30 14:43:38,513 (31916/MainThread) litecli.main ERROR - traceback: 'Traceback (most recent call last):\n  File "/home/bryan/.local/pipx/venvs/litecli/lib64/python3.6/site-packages/litecli/main.py", line 441, in one_iteration\n    for title, cur, headers, status in res:\n  File "/home/bryan/.local/pipx/venvs/litecli/lib64/python3.6/site-packages/litecli/sqlexecute.py", line 121, in run\n    for result in special.execute(cur, sql):\n  File "/home/bryan/.local/pipx/venvs/litecli/lib64/python3.6/site-packages/litecli/packages/special/iocommands.py", line 210, in execute_favorite_query\n    cur.execute(sql)\nsqlite3.OperationalError: unrecognized token: "\\"\n'
2020-04-30 14:44:08,188 (477/MainThread) litecli.main ERROR - sql: '\\f v \\', error: ValueError('No escaped character',)
2020-04-30 14:44:08,190 (477/MainThread) litecli.main ERROR - traceback: 'Traceback (most recent call last):\n  File "/home/bryan/.local/pipx/venvs/litecli/lib64/python3.6/site-packages/litecli/main.py", line 441, in one_iteration\n    for title, cur, headers, status in res:\n  File "/home/bryan/.local/pipx/venvs/litecli/lib64/python3.6/site-packages/litecli/sqlexecute.py", line 121, in run\n    for result in special.execute(cur, sql):\n  File "/home/bryan/.local/pipx/venvs/litecli/lib64/python3.6/site-packages/litecli/packages/special/iocommands.py", line 186, in execute_favorite_query\n    args = shlex.split(arg_str)\n  File "/usr/lib64/python3.6/shlex.py", line 305, in split\n    return list(lex)\n  File "/usr/lib64/python3.6/shlex.py", line 295, in __next__\n    token = self.get_token()\n  File "/usr/lib64/python3.6/shlex.py", line 105, in get_token\n    raw = self.read_token()\n  File "/usr/lib64/python3.6/shlex.py", line 206, in read_token\n    raise ValueError("No escaped character")\nValueError: No escaped character\n'
2020-04-30 15:49:38,350 (18918/MainThread) litecli.main ERROR - sql: '\\v s', error: OperationalError('unrecognized token: "\\"',)
2020-04-30 15:49:38,350 (18918/MainThread) litecli.main ERROR - traceback: 'Traceback (most recent call last):\n  File "/home/bryan/.local/pipx/venvs/litecli/lib64/python3.6/site-packages/litecli/sqlexecute.py", line 121, in run\n    for result in special.execute(cur, sql):\n  File "/home/bryan/.local/pipx/venvs/litecli/lib64/python3.6/site-packages/litecli/packages/special/main.py", line 109, in execute\n    raise CommandNotFound\nlitecli.packages.special.main.CommandNotFound\n\nDuring handling of the above exception, another exception occurred:\n\nTraceback (most recent call last):\n  File "/home/bryan/.local/pipx/venvs/litecli/lib64/python3.6/site-packages/litecli/main.py", line 441, in one_iteration\n    for title, cur, headers, status in res:\n  File "/home/bryan/.local/pipx/venvs/litecli/lib64/python3.6/site-packages/litecli/sqlexecute.py", line 125, in run\n    cur.execute(sql)\nsqlite3.OperationalError: unrecognized token: "\\"\n'
2020-04-30 15:52:30,381 (20857/MainThread) litecli.main ERROR - sql: '\\f count', error: OperationalError('incomplete input',)
2020-04-30 15:52:30,382 (20857/MainThread) litecli.main ERROR - traceback: 'Traceback (most recent call last):\n  File "/home/bryan/.local/pipx/venvs/litecli/lib64/python3.6/site-packages/litecli/main.py", line 441, in one_iteration\n    for title, cur, headers, status in res:\n  File "/home/bryan/.local/pipx/venvs/litecli/lib64/python3.6/site-packages/litecli/sqlexecute.py", line 121, in run\n    for result in special.execute(cur, sql):\n  File "/home/bryan/.local/pipx/venvs/litecli/lib64/python3.6/site-packages/litecli/packages/special/iocommands.py", line 210, in execute_favorite_query\n    cur.execute(sql)\nsqlite3.OperationalError: incomplete input\n'
2020-04-30 15:57:32,745 (22522/MainThread) litecli.main ERROR - sql: '/power', error: OperationalError('near "/": syntax error',)
2020-04-30 15:57:32,746 (22522/MainThread) litecli.main ERROR - traceback: 'Traceback (most recent call last):\n  File "/home/bryan/.local/pipx/venvs/litecli/lib64/python3.6/site-packages/litecli/sqlexecute.py", line 121, in run\n    for result in special.execute(cur, sql):\n  File "/home/bryan/.local/pipx/venvs/litecli/lib64/python3.6/site-packages/litecli/packages/special/main.py", line 109, in execute\n    raise CommandNotFound\nlitecli.packages.special.main.CommandNotFound\n\nDuring handling of the above exception, another exception occurred:\n\nTraceback (most recent call last):\n  File "/home/bryan/.local/pipx/venvs/litecli/lib64/python3.6/site-packages/litecli/main.py", line 441, in one_iteration\n    for title, cur, headers, status in res:\n  File "/home/bryan/.local/pipx/venvs/litecli/lib64/python3.6/site-packages/litecli/sqlexecute.py", line 125, in run\n    cur.execute(sql)\nsqlite3.OperationalError: near "/": syntax error\n'
2020-05-02 14:37:51,632 (1824/MainThread) litecli.main ERROR - sql: 'alter table jobs add primary key id autoincrement', error: OperationalError('near "primary": syntax error',)
2020-05-02 14:37:51,637 (1824/MainThread) litecli.main ERROR - traceback: 'Traceback (most recent call last):\n  File "/home/bryan/.local/pipx/venvs/litecli/lib64/python3.6/site-packages/litecli/sqlexecute.py", line 121, in run\n    for result in special.execute(cur, sql):\n  File "/home/bryan/.local/pipx/venvs/litecli/lib64/python3.6/site-packages/litecli/packages/special/main.py", line 109, in execute\n    raise CommandNotFound\nlitecli.packages.special.main.CommandNotFound\n\nDuring handling of the above exception, another exception occurred:\n\nTraceback (most recent call last):\n  File "/home/bryan/.local/pipx/venvs/litecli/lib64/python3.6/site-packages/litecli/main.py", line 441, in one_iteration\n    for title, cur, headers, status in res:\n  File "/home/bryan/.local/pipx/venvs/litecli/lib64/python3.6/site-packages/litecli/sqlexecute.py", line 125, in run\n    cur.execute(sql)\nsqlite3.OperationalError: near "primary": syntax error\n'
2020-05-02 14:38:05,043 (1824/MainThread) litecli.main ERROR - sql: 'alter table jobs add primary key autoincrement id', error: OperationalError('near "primary": syntax error',)
2020-05-02 14:38:05,044 (1824/MainThread) litecli.main ERROR - traceback: 'Traceback (most recent call last):\n  File "/home/bryan/.local/pipx/venvs/litecli/lib64/python3.6/site-packages/litecli/sqlexecute.py", line 121, in run\n    for result in special.execute(cur, sql):\n  File "/home/bryan/.local/pipx/venvs/litecli/lib64/python3.6/site-packages/litecli/packages/special/main.py", line 109, in execute\n    raise CommandNotFound\nlitecli.packages.special.main.CommandNotFound\n\nDuring handling of the above exception, another exception occurred:\n\nTraceback (most recent call last):\n  File "/home/bryan/.local/pipx/venvs/litecli/lib64/python3.6/site-packages/litecli/main.py", line 441, in one_iteration\n    for title, cur, headers, status in res:\n  File "/home/bryan/.local/pipx/venvs/litecli/lib64/python3.6/site-packages/litecli/sqlexecute.py", line 125, in run\n    cur.execute(sql)\nsqlite3.OperationalError: near "primary": syntax error\n'
2020-05-02 14:41:05,006 (1824/MainThread) litecli.main ERROR - sql: 'alter table jobs add primary key id', error: OperationalError('near "primary": syntax error',)
2020-05-02 14:41:05,007 (1824/MainThread) litecli.main ERROR - traceback: 'Traceback (most recent call last):\n  File "/home/bryan/.local/pipx/venvs/litecli/lib64/python3.6/site-packages/litecli/sqlexecute.py", line 121, in run\n    for result in special.execute(cur, sql):\n  File "/home/bryan/.local/pipx/venvs/litecli/lib64/python3.6/site-packages/litecli/packages/special/main.py", line 109, in execute\n    raise CommandNotFound\nlitecli.packages.special.main.CommandNotFound\n\nDuring handling of the above exception, another exception occurred:\n\nTraceback (most recent call last):\n  File "/home/bryan/.local/pipx/venvs/litecli/lib64/python3.6/site-packages/litecli/main.py", line 441, in one_iteration\n    for title, cur, headers, status in res:\n  File "/home/bryan/.local/pipx/venvs/litecli/lib64/python3.6/site-packages/litecli/sqlexecute.py", line 125, in run\n    cur.execute(sql)\nsqlite3.OperationalError: near "primary": syntax error\n'
2020-05-02 14:41:20,203 (1824/MainThread) litecli.main ERROR - sql: 'alter table jobs add id primary key', error: OperationalError('duplicate column name: id',)
2020-05-02 14:41:20,204 (1824/MainThread) litecli.main ERROR - traceback: 'Traceback (most recent call last):\n  File "/home/bryan/.local/pipx/venvs/litecli/lib64/python3.6/site-packages/litecli/sqlexecute.py", line 121, in run\n    for result in special.execute(cur, sql):\n  File "/home/bryan/.local/pipx/venvs/litecli/lib64/python3.6/site-packages/litecli/packages/special/main.py", line 109, in execute\n    raise CommandNotFound\nlitecli.packages.special.main.CommandNotFound\n\nDuring handling of the above exception, another exception occurred:\n\nTraceback (most recent call last):\n  File "/home/bryan/.local/pipx/venvs/litecli/lib64/python3.6/site-packages/litecli/main.py", line 441, in one_iteration\n    for title, cur, headers, status in res:\n  File "/home/bryan/.local/pipx/venvs/litecli/lib64/python3.6/site-packages/litecli/sqlexecute.py", line 125, in run\n    cur.execute(sql)\nsqlite3.OperationalError: duplicate column name: id\n'
2020-05-02 14:41:33,799 (1824/MainThread) litecli.main ERROR - sql: 'alter table jobs add primary key (id)', error: OperationalError('near "primary": syntax error',)
2020-05-02 14:41:33,799 (1824/MainThread) litecli.main ERROR - traceback: 'Traceback (most recent call last):\n  File "/home/bryan/.local/pipx/venvs/litecli/lib64/python3.6/site-packages/litecli/sqlexecute.py", line 121, in run\n    for result in special.execute(cur, sql):\n  File "/home/bryan/.local/pipx/venvs/litecli/lib64/python3.6/site-packages/litecli/packages/special/main.py", line 109, in execute\n    raise CommandNotFound\nlitecli.packages.special.main.CommandNotFound\n\nDuring handling of the above exception, another exception occurred:\n\nTraceback (most recent call last):\n  File "/home/bryan/.local/pipx/venvs/litecli/lib64/python3.6/site-packages/litecli/main.py", line 441, in one_iteration\n    for title, cur, headers, status in res:\n  File "/home/bryan/.local/pipx/venvs/litecli/lib64/python3.6/site-packages/litecli/sqlexecute.py", line 125, in run\n    cur.execute(sql)\nsqlite3.OperationalError: near "primary": syntax error\n'
2020-05-02 14:41:39,133 (1824/MainThread) litecli.main ERROR - sql: 'alter table jobs add primary key id;', error: OperationalError('near "primary": syntax error',)
2020-05-02 14:41:39,133 (1824/MainThread) litecli.main ERROR - traceback: 'Traceback (most recent call last):\n  File "/home/bryan/.local/pipx/venvs/litecli/lib64/python3.6/site-packages/litecli/sqlexecute.py", line 121, in run\n    for result in special.execute(cur, sql):\n  File "/home/bryan/.local/pipx/venvs/litecli/lib64/python3.6/site-packages/litecli/packages/special/main.py", line 109, in execute\n    raise CommandNotFound\nlitecli.packages.special.main.CommandNotFound\n\nDuring handling of the above exception, another exception occurred:\n\nTraceback (most recent call last):\n  File "/home/bryan/.local/pipx/venvs/litecli/lib64/python3.6/site-packages/litecli/main.py", line 441, in one_iteration\n    for title, cur, headers, status in res:\n  File "/home/bryan/.local/pipx/venvs/litecli/lib64/python3.6/site-packages/litecli/sqlexecute.py", line 125, in run\n    cur.execute(sql)\nsqlite3.OperationalError: near "primary": syntax error\n'
2020-05-02 14:42:15,447 (1824/MainThread) litecli.main ERROR - sql: 'alter table jobs add constraint PK_id primary key id;', error: OperationalError('near "constraint": syntax error',)
2020-05-02 14:42:15,447 (1824/MainThread) litecli.main ERROR - traceback: 'Traceback (most recent call last):\n  File "/home/bryan/.local/pipx/venvs/litecli/lib64/python3.6/site-packages/litecli/sqlexecute.py", line 121, in run\n    for result in special.execute(cur, sql):\n  File "/home/bryan/.local/pipx/venvs/litecli/lib64/python3.6/site-packages/litecli/packages/special/main.py", line 109, in execute\n    raise CommandNotFound\nlitecli.packages.special.main.CommandNotFound\n\nDuring handling of the above exception, another exception occurred:\n\nTraceback (most recent call last):\n  File "/home/bryan/.local/pipx/venvs/litecli/lib64/python3.6/site-packages/litecli/main.py", line 441, in one_iteration\n    for title, cur, headers, status in res:\n  File "/home/bryan/.local/pipx/venvs/litecli/lib64/python3.6/site-packages/litecli/sqlexecute.py", line 125, in run\n    cur.execute(sql)\nsqlite3.OperationalError: near "constraint": syntax error\n'
2020-05-02 14:43:14,456 (1824/MainThread) litecli.main ERROR - sql: 'TE TABLE IF NOT EXISTS new_jobs (', error: OperationalError('near "TE": syntax error',)
2020-05-02 14:43:14,456 (1824/MainThread) litecli.main ERROR - traceback: 'Traceback (most recent call last):\n  File "/home/bryan/.local/pipx/venvs/litecli/lib64/python3.6/site-packages/litecli/sqlexecute.py", line 121, in run\n    for result in special.execute(cur, sql):\n  File "/home/bryan/.local/pipx/venvs/litecli/lib64/python3.6/site-packages/litecli/packages/special/main.py", line 109, in execute\n    raise CommandNotFound\nlitecli.packages.special.main.CommandNotFound\n\nDuring handling of the above exception, another exception occurred:\n\nTraceback (most recent call last):\n  File "/home/bryan/.local/pipx/venvs/litecli/lib64/python3.6/site-packages/litecli/main.py", line 441, in one_iteration\n    for title, cur, headers, status in res:\n  File "/home/bryan/.local/pipx/venvs/litecli/lib64/python3.6/site-packages/litecli/sqlexecute.py", line 125, in run\n    cur.execute(sql)\nsqlite3.OperationalError: near "TE": syntax error\n'
2020-05-02 14:43:14,479 (1824/MainThread) litecli.main ERROR - sql: '    id INTEGER PRIMARY KEY,', error: OperationalError('near "id": syntax error',)
2020-05-02 14:43:14,479 (1824/MainThread) litecli.main ERROR - traceback: 'Traceback (most recent call last):\n  File "/home/bryan/.local/pipx/venvs/litecli/lib64/python3.6/site-packages/litecli/sqlexecute.py", line 121, in run\n    for result in special.execute(cur, sql):\n  File "/home/bryan/.local/pipx/venvs/litecli/lib64/python3.6/site-packages/litecli/packages/special/main.py", line 109, in execute\n    raise CommandNotFound\nlitecli.packages.special.main.CommandNotFound\n\nDuring handling of the above exception, another exception occurred:\n\nTraceback (most recent call last):\n  File "/home/bryan/.local/pipx/venvs/litecli/lib64/python3.6/site-packages/litecli/main.py", line 441, in one_iteration\n    for title, cur, headers, status in res:\n  File "/home/bryan/.local/pipx/venvs/litecli/lib64/python3.6/site-packages/litecli/sqlexecute.py", line 125, in run\n    cur.execute(sql)\nsqlite3.OperationalError: near "id": syntax error\n'
2020-05-02 14:43:14,498 (1824/MainThread) litecli.main ERROR - sql: '    title TEXT,', error: OperationalError('near "title": syntax error',)
2020-05-02 14:43:14,498 (1824/MainThread) litecli.main ERROR - traceback: 'Traceback (most recent call last):\n  File "/home/bryan/.local/pipx/venvs/litecli/lib64/python3.6/site-packages/litecli/sqlexecute.py", line 121, in run\n    for result in special.execute(cur, sql):\n  File "/home/bryan/.local/pipx/venvs/litecli/lib64/python3.6/site-packages/litecli/packages/special/main.py", line 109, in execute\n    raise CommandNotFound\nlitecli.packages.special.main.CommandNotFound\n\nDuring handling of the above exception, another exception occurred:\n\nTraceback (most recent call last):\n  File "/home/bryan/.local/pipx/venvs/litecli/lib64/python3.6/site-packages/litecli/main.py", line 441, in one_iteration\n    for title, cur, headers, status in res:\n  File "/home/bryan/.local/pipx/venvs/litecli/lib64/python3.6/site-packages/litecli/sqlexecute.py", line 125, in run\n    cur.execute(sql)\nsqlite3.OperationalError: near "title": syntax error\n'
2020-05-02 14:43:14,516 (1824/MainThread) litecli.main ERROR - sql: '    company TEXT,', error: OperationalError('near "company": syntax error',)
2020-05-02 14:43:14,516 (1824/MainThread) litecli.main ERROR - traceback: 'Traceback (most recent call last):\n  File "/home/bryan/.local/pipx/venvs/litecli/lib64/python3.6/site-packages/litecli/sqlexecute.py", line 121, in run\n    for result in special.execute(cur, sql):\n  File "/home/bryan/.local/pipx/venvs/litecli/lib64/python3.6/site-packages/litecli/packages/special/main.py", line 109, in execute\n    raise CommandNotFound\nlitecli.packages.special.main.CommandNotFound\n\nDuring handling of the above exception, another exception occurred:\n\nTraceback (most recent call last):\n  File "/home/bryan/.local/pipx/venvs/litecli/lib64/python3.6/site-packages/litecli/main.py", line 441, in one_iteration\n    for title, cur, headers, status in res:\n  File "/home/bryan/.local/pipx/venvs/litecli/lib64/python3.6/site-packages/litecli/sqlexecute.py", line 125, in run\n    cur.execute(sql)\nsqlite3.OperationalError: near "company": syntax error\n'
2020-05-02 14:43:14,533 (1824/MainThread) litecli.main ERROR - sql: '    location TEXT,', error: OperationalError('near "location": syntax error',)
2020-05-02 14:43:14,534 (1824/MainThread) litecli.main ERROR - traceback: 'Traceback (most recent call last):\n  File "/home/bryan/.local/pipx/venvs/litecli/lib64/python3.6/site-packages/litecli/sqlexecute.py", line 121, in run\n    for result in special.execute(cur, sql):\n  File "/home/bryan/.local/pipx/venvs/litecli/lib64/python3.6/site-packages/litecli/packages/special/main.py", line 109, in execute\n    raise CommandNotFound\nlitecli.packages.special.main.CommandNotFound\n\nDuring handling of the above exception, another exception occurred:\n\nTraceback (most recent call last):\n  File "/home/bryan/.local/pipx/venvs/litecli/lib64/python3.6/site-packages/litecli/main.py", line 441, in one_iteration\n    for title, cur, headers, status in res:\n  File "/home/bryan/.local/pipx/venvs/litecli/lib64/python3.6/site-packages/litecli/sqlexecute.py", line 125, in run\n    cur.execute(sql)\nsqlite3.OperationalError: near "location": syntax error\n'
2020-05-02 14:43:14,552 (1824/MainThread) litecli.main ERROR - sql: '    post_date TEXT,', error: OperationalError('near "post_date": syntax error',)
2020-05-02 14:43:14,552 (1824/MainThread) litecli.main ERROR - traceback: 'Traceback (most recent call last):\n  File "/home/bryan/.local/pipx/venvs/litecli/lib64/python3.6/site-packages/litecli/sqlexecute.py", line 121, in run\n    for result in special.execute(cur, sql):\n  File "/home/bryan/.local/pipx/venvs/litecli/lib64/python3.6/site-packages/litecli/packages/special/main.py", line 109, in execute\n    raise CommandNotFound\nlitecli.packages.special.main.CommandNotFound\n\nDuring handling of the above exception, another exception occurred:\n\nTraceback (most recent call last):\n  File "/home/bryan/.local/pipx/venvs/litecli/lib64/python3.6/site-packages/litecli/main.py", line 441, in one_iteration\n    for title, cur, headers, status in res:\n  File "/home/bryan/.local/pipx/venvs/litecli/lib64/python3.6/site-packages/litecli/sqlexecute.py", line 125, in run\n    cur.execute(sql)\nsqlite3.OperationalError: near "post_date": syntax error\n'
2020-05-02 14:43:14,582 (1824/MainThread) litecli.main ERROR - sql: '    modify_date TEXT,', error: OperationalError('near "modify_date": syntax error',)
2020-05-02 14:43:14,582 (1824/MainThread) litecli.main ERROR - traceback: 'Traceback (most recent call last):\n  File "/home/bryan/.local/pipx/venvs/litecli/lib64/python3.6/site-packages/litecli/sqlexecute.py", line 121, in run\n    for result in special.execute(cur, sql):\n  File "/home/bryan/.local/pipx/venvs/litecli/lib64/python3.6/site-packages/litecli/packages/special/main.py", line 109, in execute\n    raise CommandNotFound\nlitecli.packages.special.main.CommandNotFound\n\nDuring handling of the above exception, another exception occurred:\n\nTraceback (most recent call last):\n  File "/home/bryan/.local/pipx/venvs/litecli/lib64/python3.6/site-packages/litecli/main.py", line 441, in one_iteration\n    for title, cur, headers, status in res:\n  File "/home/bryan/.local/pipx/venvs/litecli/lib64/python3.6/site-packages/litecli/sqlexecute.py", line 125, in run\n    cur.execute(sql)\nsqlite3.OperationalError: near "modify_date": syntax error\n'
2020-05-02 14:43:14,602 (1824/MainThread) litecli.main ERROR - sql: '    creation_date TEXT,', error: OperationalError('near "creation_date": syntax error',)
2020-05-02 14:43:14,602 (1824/MainThread) litecli.main ERROR - traceback: 'Traceback (most recent call last):\n  File "/home/bryan/.local/pipx/venvs/litecli/lib64/python3.6/site-packages/litecli/sqlexecute.py", line 121, in run\n    for result in special.execute(cur, sql):\n  File "/home/bryan/.local/pipx/venvs/litecli/lib64/python3.6/site-packages/litecli/packages/special/main.py", line 109, in execute\n    raise CommandNotFound\nlitecli.packages.special.main.CommandNotFound\n\nDuring handling of the above exception, another exception occurred:\n\nTraceback (most recent call last):\n  File "/home/bryan/.local/pipx/venvs/litecli/lib64/python3.6/site-packages/litecli/main.py", line 441, in one_iteration\n    for title, cur, headers, status in res:\n  File "/home/bryan/.local/pipx/venvs/litecli/lib64/python3.6/site-packages/litecli/sqlexecute.py", line 125, in run\n    cur.execute(sql)\nsqlite3.OperationalError: near "creation_date": syntax error\n'
2020-05-02 14:43:14,618 (1824/MainThread) litecli.main ERROR - sql: '    url TEXT,', error: OperationalError('near "url": syntax error',)
2020-05-02 14:43:14,619 (1824/MainThread) litecli.main ERROR - traceback: 'Traceback (most recent call last):\n  File "/home/bryan/.local/pipx/venvs/litecli/lib64/python3.6/site-packages/litecli/sqlexecute.py", line 121, in run\n    for result in special.execute(cur, sql):\n  File "/home/bryan/.local/pipx/venvs/litecli/lib64/python3.6/site-packages/litecli/packages/special/main.py", line 109, in execute\n    raise CommandNotFound\nlitecli.packages.special.main.CommandNotFound\n\nDuring handling of the above exception, another exception occurred:\n\nTraceback (most recent call last):\n  File "/home/bryan/.local/pipx/venvs/litecli/lib64/python3.6/site-packages/litecli/main.py", line 441, in one_iteration\n    for title, cur, headers, status in res:\n  File "/home/bryan/.local/pipx/venvs/litecli/lib64/python3.6/site-packages/litecli/sqlexecute.py", line 125, in run\n    cur.execute(sql)\nsqlite3.OperationalError: near "url": syntax error\n'
2020-05-02 14:43:14,635 (1824/MainThread) litecli.main ERROR - sql: '    desc TEXT,', error: OperationalError('near ",": syntax error',)
2020-05-02 14:43:14,637 (1824/MainThread) litecli.main ERROR - traceback: 'Traceback (most recent call last):\n  File "/home/bryan/.local/pipx/venvs/litecli/lib64/python3.6/site-packages/litecli/main.py", line 441, in one_iteration\n    for title, cur, headers, status in res:\n  File "/home/bryan/.local/pipx/venvs/litecli/lib64/python3.6/site-packages/litecli/sqlexecute.py", line 121, in run\n    for result in special.execute(cur, sql):\n  File "/home/bryan/.local/pipx/venvs/litecli/lib64/python3.6/site-packages/litecli/packages/special/main.py", line 121, in execute\n    return special_cmd.handler(cur=cur, arg=arg, verbose=verbose)\n  File "/home/bryan/.local/pipx/venvs/litecli/lib64/python3.6/site-packages/litecli/packages/special/dbcommands.py", line 194, in describe\n    cur.execute(query)\nsqlite3.OperationalError: near ",": syntax error\n'
2020-05-02 14:43:14,656 (1824/MainThread) litecli.main ERROR - sql: '    score INTEGER,', error: OperationalError('near "score": syntax error',)
2020-05-02 14:43:14,656 (1824/MainThread) litecli.main ERROR - traceback: 'Traceback (most recent call last):\n  File "/home/bryan/.local/pipx/venvs/litecli/lib64/python3.6/site-packages/litecli/sqlexecute.py", line 121, in run\n    for result in special.execute(cur, sql):\n  File "/home/bryan/.local/pipx/venvs/litecli/lib64/python3.6/site-packages/litecli/packages/special/main.py", line 109, in execute\n    raise CommandNotFound\nlitecli.packages.special.main.CommandNotFound\n\nDuring handling of the above exception, another exception occurred:\n\nTraceback (most recent call last):\n  File "/home/bryan/.local/pipx/venvs/litecli/lib64/python3.6/site-packages/litecli/main.py", line 441, in one_iteration\n    for title, cur, headers, status in res:\n  File "/home/bryan/.local/pipx/venvs/litecli/lib64/python3.6/site-packages/litecli/sqlexecute.py", line 125, in run\n    cur.execute(sql)\nsqlite3.OperationalError: near "score": syntax error\n'
2020-05-02 14:43:14,685 (1824/MainThread) litecli.main ERROR - sql: '    scorecard TEXT,', error: OperationalError('near "scorecard": syntax error',)
2020-05-02 14:43:14,685 (1824/MainThread) litecli.main ERROR - traceback: 'Traceback (most recent call last):\n  File "/home/bryan/.local/pipx/venvs/litecli/lib64/python3.6/site-packages/litecli/sqlexecute.py", line 121, in run\n    for result in special.execute(cur, sql):\n  File "/home/bryan/.local/pipx/venvs/litecli/lib64/python3.6/site-packages/litecli/packages/special/main.py", line 109, in execute\n    raise CommandNotFound\nlitecli.packages.special.main.CommandNotFound\n\nDuring handling of the above exception, another exception occurred:\n\nTraceback (most recent call last):\n  File "/home/bryan/.local/pipx/venvs/litecli/lib64/python3.6/site-packages/litecli/main.py", line 441, in one_iteration\n    for title, cur, headers, status in res:\n  File "/home/bryan/.local/pipx/venvs/litecli/lib64/python3.6/site-packages/litecli/sqlexecute.py", line 125, in run\n    cur.execute(sql)\nsqlite3.OperationalError: near "scorecard": syntax error\n'
2020-05-02 14:43:14,719 (1824/MainThread) litecli.main ERROR - sql: '    search_keywords TEXT,', error: OperationalError('near "search_keywords": syntax error',)
2020-05-02 14:43:14,720 (1824/MainThread) litecli.main ERROR - traceback: 'Traceback (most recent call last):\n  File "/home/bryan/.local/pipx/venvs/litecli/lib64/python3.6/site-packages/litecli/sqlexecute.py", line 121, in run\n    for result in special.execute(cur, sql):\n  File "/home/bryan/.local/pipx/venvs/litecli/lib64/python3.6/site-packages/litecli/packages/special/main.py", line 109, in execute\n    raise CommandNotFound\nlitecli.packages.special.main.CommandNotFound\n\nDuring handling of the above exception, another exception occurred:\n\nTraceback (most recent call last):\n  File "/home/bryan/.local/pipx/venvs/litecli/lib64/python3.6/site-packages/litecli/main.py", line 441, in one_iteration\n    for title, cur, headers, status in res:\n  File "/home/bryan/.local/pipx/venvs/litecli/lib64/python3.6/site-packages/litecli/sqlexecute.py", line 125, in run\n    cur.execute(sql)\nsqlite3.OperationalError: near "search_keywords": syntax error\n'
2020-05-02 14:43:14,741 (1824/MainThread) litecli.main ERROR - sql: '    search_location TEXT,', error: OperationalError('near "search_location": syntax error',)
2020-05-02 14:43:14,742 (1824/MainThread) litecli.main ERROR - traceback: 'Traceback (most recent call last):\n  File "/home/bryan/.local/pipx/venvs/litecli/lib64/python3.6/site-packages/litecli/sqlexecute.py", line 121, in run\n    for result in special.execute(cur, sql):\n  File "/home/bryan/.local/pipx/venvs/litecli/lib64/python3.6/site-packages/litecli/packages/special/main.py", line 109, in execute\n    raise CommandNotFound\nlitecli.packages.special.main.CommandNotFound\n\nDuring handling of the above exception, another exception occurred:\n\nTraceback (most recent call last):\n  File "/home/bryan/.local/pipx/venvs/litecli/lib64/python3.6/site-packages/litecli/main.py", line 441, in one_iteration\n    for title, cur, headers, status in res:\n  File "/home/bryan/.local/pipx/venvs/litecli/lib64/python3.6/site-packages/litecli/sqlexecute.py", line 125, in run\n    cur.execute(sql)\nsqlite3.OperationalError: near "search_location": syntax error\n'
2020-05-02 14:43:14,871 (1824/MainThread) litecli.main ERROR - sql: '    UNIQUE(title, company, post_date, location)', error: OperationalError('near "UNIQUE": syntax error',)
2020-05-02 14:43:14,871 (1824/MainThread) litecli.main ERROR - traceback: 'Traceback (most recent call last):\n  File "/home/bryan/.local/pipx/venvs/litecli/lib64/python3.6/site-packages/litecli/sqlexecute.py", line 121, in run\n    for result in special.execute(cur, sql):\n  File "/home/bryan/.local/pipx/venvs/litecli/lib64/python3.6/site-packages/litecli/packages/special/main.py", line 109, in execute\n    raise CommandNotFound\nlitecli.packages.special.main.CommandNotFound\n\nDuring handling of the above exception, another exception occurred:\n\nTraceback (most recent call last):\n  File "/home/bryan/.local/pipx/venvs/litecli/lib64/python3.6/site-packages/litecli/main.py", line 441, in one_iteration\n    for title, cur, headers, status in res:\n  File "/home/bryan/.local/pipx/venvs/litecli/lib64/python3.6/site-packages/litecli/sqlexecute.py", line 125, in run\n    cur.execute(sql)\nsqlite3.OperationalError: near "UNIQUE": syntax error\n'
2020-05-02 14:43:14,882 (1824/MainThread) litecli.main ERROR - sql: ')', error: OperationalError('near ")": syntax error',)
2020-05-02 14:43:14,883 (1824/MainThread) litecli.main ERROR - traceback: 'Traceback (most recent call last):\n  File "/home/bryan/.local/pipx/venvs/litecli/lib64/python3.6/site-packages/litecli/sqlexecute.py", line 121, in run\n    for result in special.execute(cur, sql):\n  File "/home/bryan/.local/pipx/venvs/litecli/lib64/python3.6/site-packages/litecli/packages/special/main.py", line 109, in execute\n    raise CommandNotFound\nlitecli.packages.special.main.CommandNotFound\n\nDuring handling of the above exception, another exception occurred:\n\nTraceback (most recent call last):\n  File "/home/bryan/.local/pipx/venvs/litecli/lib64/python3.6/site-packages/litecli/main.py", line 441, in one_iteration\n    for title, cur, headers, status in res:\n  File "/home/bryan/.local/pipx/venvs/litecli/lib64/python3.6/site-packages/litecli/sqlexecute.py", line 125, in run\n    cur.execute(sql)\nsqlite3.OperationalError: near ")": syntax error\n'
2020-05-02 14:45:45,102 (1824/MainThread) litecli.main ERROR - sql: 'insert into new_jobs select * from jobs;', error: IntegrityError('datatype mismatch',)
2020-05-02 14:45:45,103 (1824/MainThread) litecli.main ERROR - traceback: 'Traceback (most recent call last):\n  File "/home/bryan/.local/pipx/venvs/litecli/lib64/python3.6/site-packages/litecli/sqlexecute.py", line 121, in run\n    for result in special.execute(cur, sql):\n  File "/home/bryan/.local/pipx/venvs/litecli/lib64/python3.6/site-packages/litecli/packages/special/main.py", line 109, in execute\n    raise CommandNotFound\nlitecli.packages.special.main.CommandNotFound\n\nDuring handling of the above exception, another exception occurred:\n\nTraceback (most recent call last):\n  File "/home/bryan/.local/pipx/venvs/litecli/lib64/python3.6/site-packages/litecli/main.py", line 441, in one_iteration\n    for title, cur, headers, status in res:\n  File "/home/bryan/.local/pipx/venvs/litecli/lib64/python3.6/site-packages/litecli/sqlexecute.py", line 125, in run\n    cur.execute(sql)\nsqlite3.IntegrityError: datatype mismatch\n'
2020-05-02 14:45:55,045 (1824/MainThread) litecli.main ERROR - sql: 'insert into new_jobs select * from jobs', error: IntegrityError('datatype mismatch',)
2020-05-02 14:45:55,045 (1824/MainThread) litecli.main ERROR - traceback: 'Traceback (most recent call last):\n  File "/home/bryan/.local/pipx/venvs/litecli/lib64/python3.6/site-packages/litecli/sqlexecute.py", line 121, in run\n    for result in special.execute(cur, sql):\n  File "/home/bryan/.local/pipx/venvs/litecli/lib64/python3.6/site-packages/litecli/packages/special/main.py", line 109, in execute\n    raise CommandNotFound\nlitecli.packages.special.main.CommandNotFound\n\nDuring handling of the above exception, another exception occurred:\n\nTraceback (most recent call last):\n  File "/home/bryan/.local/pipx/venvs/litecli/lib64/python3.6/site-packages/litecli/main.py", line 441, in one_iteration\n    for title, cur, headers, status in res:\n  File "/home/bryan/.local/pipx/venvs/litecli/lib64/python3.6/site-packages/litecli/sqlexecute.py", line 125, in run\n    cur.execute(sql)\nsqlite3.IntegrityError: datatype mismatch\n'
2020-05-02 14:47:09,164 (1824/MainThread) litecli.main ERROR - sql: 'insert into new_jobs (title, company, location, post_date, modify_date, creation_date, url, desc, score, scorecard, search_keywords, search_location) select (title, company, location, post_date, modify_date, creation_date, url, desc, score, scorecard, search_keywords, search_location) from jobs', error: OperationalError('row value misused',)
2020-05-02 14:47:09,164 (1824/MainThread) litecli.main ERROR - traceback: 'Traceback (most recent call last):\n  File "/home/bryan/.local/pipx/venvs/litecli/lib64/python3.6/site-packages/litecli/sqlexecute.py", line 121, in run\n    for result in special.execute(cur, sql):\n  File "/home/bryan/.local/pipx/venvs/litecli/lib64/python3.6/site-packages/litecli/packages/special/main.py", line 109, in execute\n    raise CommandNotFound\nlitecli.packages.special.main.CommandNotFound\n\nDuring handling of the above exception, another exception occurred:\n\nTraceback (most recent call last):\n  File "/home/bryan/.local/pipx/venvs/litecli/lib64/python3.6/site-packages/litecli/main.py", line 441, in one_iteration\n    for title, cur, headers, status in res:\n  File "/home/bryan/.local/pipx/venvs/litecli/lib64/python3.6/site-packages/litecli/sqlexecute.py", line 125, in run\n    cur.execute(sql)\nsqlite3.OperationalError: row value misused\n'
2020-05-02 14:47:31,078 (1824/MainThread) litecli.main ERROR - sql: 'insert into new_jobs (title, company, location, post_date, modify_date, creation_date, url, desc, score, scorecard, search_keywords, search_location) values (select (title, company, location, post_date, modify_date, creation_date, url, desc, score, scorecard, search_keywords, search_location) from jobs)', error: OperationalError('near "select": syntax error',)
2020-05-02 14:47:31,078 (1824/MainThread) litecli.main ERROR - traceback: 'Traceback (most recent call last):\n  File "/home/bryan/.local/pipx/venvs/litecli/lib64/python3.6/site-packages/litecli/sqlexecute.py", line 121, in run\n    for result in special.execute(cur, sql):\n  File "/home/bryan/.local/pipx/venvs/litecli/lib64/python3.6/site-packages/litecli/packages/special/main.py", line 109, in execute\n    raise CommandNotFound\nlitecli.packages.special.main.CommandNotFound\n\nDuring handling of the above exception, another exception occurred:\n\nTraceback (most recent call last):\n  File "/home/bryan/.local/pipx/venvs/litecli/lib64/python3.6/site-packages/litecli/main.py", line 441, in one_iteration\n    for title, cur, headers, status in res:\n  File "/home/bryan/.local/pipx/venvs/litecli/lib64/python3.6/site-packages/litecli/sqlexecute.py", line 125, in run\n    cur.execute(sql)\nsqlite3.OperationalError: near "select": syntax error\n'
2020-05-02 14:47:39,518 (1824/MainThread) litecli.main ERROR - sql: 'insert into new_jobs (title, company, location, post_date, modify_date, creation_date, url, desc, score, scorecard, search_keywords, search_location) (select (title, company, location, post_date, modify_date, creation_date, url, desc, score, scorecard, search_keywords, search_location) from jobs)', error: OperationalError('near "(": syntax error',)
2020-05-02 14:47:39,518 (1824/MainThread) litecli.main ERROR - traceback: 'Traceback (most recent call last):\n  File "/home/bryan/.local/pipx/venvs/litecli/lib64/python3.6/site-packages/litecli/sqlexecute.py", line 121, in run\n    for result in special.execute(cur, sql):\n  File "/home/bryan/.local/pipx/venvs/litecli/lib64/python3.6/site-packages/litecli/packages/special/main.py", line 109, in execute\n    raise CommandNotFound\nlitecli.packages.special.main.CommandNotFound\n\nDuring handling of the above exception, another exception occurred:\n\nTraceback (most recent call last):\n  File "/home/bryan/.local/pipx/venvs/litecli/lib64/python3.6/site-packages/litecli/main.py", line 441, in one_iteration\n    for title, cur, headers, status in res:\n  File "/home/bryan/.local/pipx/venvs/litecli/lib64/python3.6/site-packages/litecli/sqlexecute.py", line 125, in run\n    cur.execute(sql)\nsqlite3.OperationalError: near "(": syntax error\n'
2020-05-02 14:47:48,217 (1824/MainThread) litecli.main ERROR - sql: 'insert into new_jobs (title, company, location, post_date, modify_date, creation_date, url, desc, score, scorecard, search_keywords, search_location) select (title, company, location, post_date, modify_date, creation_date, url, desc, score, scorecard, search_keywords, search_location) from jobs', error: OperationalError('row value misused',)
2020-05-02 14:47:48,217 (1824/MainThread) litecli.main ERROR - traceback: 'Traceback (most recent call last):\n  File "/home/bryan/.local/pipx/venvs/litecli/lib64/python3.6/site-packages/litecli/sqlexecute.py", line 121, in run\n    for result in special.execute(cur, sql):\n  File "/home/bryan/.local/pipx/venvs/litecli/lib64/python3.6/site-packages/litecli/packages/special/main.py", line 109, in execute\n    raise CommandNotFound\nlitecli.packages.special.main.CommandNotFound\n\nDuring handling of the above exception, another exception occurred:\n\nTraceback (most recent call last):\n  File "/home/bryan/.local/pipx/venvs/litecli/lib64/python3.6/site-packages/litecli/main.py", line 441, in one_iteration\n    for title, cur, headers, status in res:\n  File "/home/bryan/.local/pipx/venvs/litecli/lib64/python3.6/site-packages/litecli/sqlexecute.py", line 125, in run\n    cur.execute(sql)\nsqlite3.OperationalError: row value misused\n'
2020-05-02 14:48:29,054 (1824/MainThread) litecli.main ERROR - sql: 'insert into new_jobs title, company, location, post_date, modify_date, creation_date, url, desc, score, scorecard, search_keywords, search_location select title, company, location, post_date, modify_date, creation_date, url, desc, score, scorecard, search_keywords, search_location from jobs', error: OperationalError('near "title": syntax error',)
2020-05-02 14:48:29,055 (1824/MainThread) litecli.main ERROR - traceback: 'Traceback (most recent call last):\n  File "/home/bryan/.local/pipx/venvs/litecli/lib64/python3.6/site-packages/litecli/sqlexecute.py", line 121, in run\n    for result in special.execute(cur, sql):\n  File "/home/bryan/.local/pipx/venvs/litecli/lib64/python3.6/site-packages/litecli/packages/special/main.py", line 109, in execute\n    raise CommandNotFound\nlitecli.packages.special.main.CommandNotFound\n\nDuring handling of the above exception, another exception occurred:\n\nTraceback (most recent call last):\n  File "/home/bryan/.local/pipx/venvs/litecli/lib64/python3.6/site-packages/litecli/main.py", line 441, in one_iteration\n    for title, cur, headers, status in res:\n  File "/home/bryan/.local/pipx/venvs/litecli/lib64/python3.6/site-packages/litecli/sqlexecute.py", line 125, in run\n    cur.execute(sql)\nsqlite3.OperationalError: near "title": syntax error\n'
2020-05-02 14:53:59,498 (8799/MainThread) litecli.main ERROR - sql: '\\f s 15', error: OperationalError('unrecognized token: "\\"',)
2020-05-02 14:53:59,499 (8799/MainThread) litecli.main ERROR - traceback: 'Traceback (most recent call last):\n  File "/home/bryan/.local/pipx/venvs/litecli/lib64/python3.6/site-packages/litecli/main.py", line 441, in one_iteration\n    for title, cur, headers, status in res:\n  File "/home/bryan/.local/pipx/venvs/litecli/lib64/python3.6/site-packages/litecli/sqlexecute.py", line 121, in run\n    for result in special.execute(cur, sql):\n  File "/home/bryan/.local/pipx/venvs/litecli/lib64/python3.6/site-packages/litecli/packages/special/iocommands.py", line 210, in execute_favorite_query\n    cur.execute(sql)\nsqlite3.OperationalError: unrecognized token: "\\"\n'
2020-05-02 15:02:59,293 (9331/MainThread) litecli.main ERROR - sql: '\\f cd -1000', error: OperationalError('near "desc": syntax error',)
2020-05-02 15:02:59,295 (9331/MainThread) litecli.main ERROR - traceback: 'Traceback (most recent call last):\n  File "/home/bryan/.local/pipx/venvs/litecli/lib64/python3.6/site-packages/litecli/main.py", line 441, in one_iteration\n    for title, cur, headers, status in res:\n  File "/home/bryan/.local/pipx/venvs/litecli/lib64/python3.6/site-packages/litecli/sqlexecute.py", line 121, in run\n    for result in special.execute(cur, sql):\n  File "/home/bryan/.local/pipx/venvs/litecli/lib64/python3.6/site-packages/litecli/packages/special/iocommands.py", line 210, in execute_favorite_query\n    cur.execute(sql)\nsqlite3.OperationalError: near "desc": syntax error\n'
2020-05-02 15:03:24,512 (9331/MainThread) litecli.main ERROR - sql: '\\f cd -1000', error: OperationalError('near "desc": syntax error',)
2020-05-02 15:03:24,512 (9331/MainThread) litecli.main ERROR - traceback: 'Traceback (most recent call last):\n  File "/home/bryan/.local/pipx/venvs/litecli/lib64/python3.6/site-packages/litecli/main.py", line 441, in one_iteration\n    for title, cur, headers, status in res:\n  File "/home/bryan/.local/pipx/venvs/litecli/lib64/python3.6/site-packages/litecli/sqlexecute.py", line 121, in run\n    for result in special.execute(cur, sql):\n  File "/home/bryan/.local/pipx/venvs/litecli/lib64/python3.6/site-packages/litecli/packages/special/iocommands.py", line 210, in execute_favorite_query\n    cur.execute(sql)\nsqlite3.OperationalError: near "desc": syntax error\n'
2020-05-02 15:04:52,179 (13902/MainThread) litecli.main ERROR - sql: '\\f cd -1000', error: OperationalError('near "Date": syntax error',)
2020-05-02 15:04:52,179 (13902/MainThread) litecli.main ERROR - traceback: 'Traceback (most recent call last):\n  File "/home/bryan/.local/pipx/venvs/litecli/lib64/python3.6/site-packages/litecli/main.py", line 441, in one_iteration\n    for title, cur, headers, status in res:\n  File "/home/bryan/.local/pipx/venvs/litecli/lib64/python3.6/site-packages/litecli/sqlexecute.py", line 121, in run\n    for result in special.execute(cur, sql):\n  File "/home/bryan/.local/pipx/venvs/litecli/lib64/python3.6/site-packages/litecli/packages/special/iocommands.py", line 210, in execute_favorite_query\n    cur.execute(sql)\nsqlite3.OperationalError: near "Date": syntax error\n'
2020-05-02 15:04:56,045 (13902/MainThread) litecli.main ERROR - sql: '\\f cd -1000', error: OperationalError('near "Date": syntax error',)
2020-05-02 15:04:56,045 (13902/MainThread) litecli.main ERROR - traceback: 'Traceback (most recent call last):\n  File "/home/bryan/.local/pipx/venvs/litecli/lib64/python3.6/site-packages/litecli/main.py", line 441, in one_iteration\n    for title, cur, headers, status in res:\n  File "/home/bryan/.local/pipx/venvs/litecli/lib64/python3.6/site-packages/litecli/sqlexecute.py", line 121, in run\n    for result in special.execute(cur, sql):\n  File "/home/bryan/.local/pipx/venvs/litecli/lib64/python3.6/site-packages/litecli/packages/special/iocommands.py", line 210, in execute_favorite_query\n    cur.execute(sql)\nsqlite3.OperationalError: near "Date": syntax error\n'
2020-05-02 15:06:23,278 (16234/MainThread) litecli.main ERROR - sql: '\\f cd -1000', error: OperationalError('row value misused',)
2020-05-02 15:06:23,279 (16234/MainThread) litecli.main ERROR - traceback: 'Traceback (most recent call last):\n  File "/home/bryan/.local/pipx/venvs/litecli/lib64/python3.6/site-packages/litecli/main.py", line 441, in one_iteration\n    for title, cur, headers, status in res:\n  File "/home/bryan/.local/pipx/venvs/litecli/lib64/python3.6/site-packages/litecli/sqlexecute.py", line 121, in run\n    for result in special.execute(cur, sql):\n  File "/home/bryan/.local/pipx/venvs/litecli/lib64/python3.6/site-packages/litecli/packages/special/iocommands.py", line 210, in execute_favorite_query\n    cur.execute(sql)\nsqlite3.OperationalError: row value misused\n'
2020-05-02 15:18:13,070 (28204/MainThread) litecli.main ERROR - sql: '\\f cd -1000', error: OperationalError('no such column: Creation',)
2020-05-02 15:18:13,070 (28204/MainThread) litecli.main ERROR - traceback: 'Traceback (most recent call last):\n  File "/home/bryan/.local/pipx/venvs/litecli/lib64/python3.6/site-packages/litecli/main.py", line 441, in one_iteration\n    for title, cur, headers, status in res:\n  File "/home/bryan/.local/pipx/venvs/litecli/lib64/python3.6/site-packages/litecli/sqlexecute.py", line 121, in run\n    for result in special.execute(cur, sql):\n  File "/home/bryan/.local/pipx/venvs/litecli/lib64/python3.6/site-packages/litecli/packages/special/iocommands.py", line 210, in execute_favorite_query\n    cur.execute(sql)\nsqlite3.OperationalError: no such column: Creation\n'
2020-05-04 14:30:34,607 (9708/MainThread) litecli.main ERROR - sql: '\\qf s 20', error: OperationalError('unrecognized token: "\\"',)
2020-05-04 14:30:34,608 (9708/MainThread) litecli.main ERROR - traceback: 'Traceback (most recent call last):\n  File "/home/bryan/.local/pipx/venvs/litecli/lib64/python3.6/site-packages/litecli/sqlexecute.py", line 121, in run\n    for result in special.execute(cur, sql):\n  File "/home/bryan/.local/pipx/venvs/litecli/lib64/python3.6/site-packages/litecli/packages/special/main.py", line 109, in execute\n    raise CommandNotFound\nlitecli.packages.special.main.CommandNotFound\n\nDuring handling of the above exception, another exception occurred:\n\nTraceback (most recent call last):\n  File "/home/bryan/.local/pipx/venvs/litecli/lib64/python3.6/site-packages/litecli/main.py", line 441, in one_iteration\n    for title, cur, headers, status in res:\n  File "/home/bryan/.local/pipx/venvs/litecli/lib64/python3.6/site-packages/litecli/sqlexecute.py", line 125, in run\n    cur.execute(sql)\nsqlite3.OperationalError: unrecognized token: "\\"\n'
2020-06-08 19:50:14,370 (5954/MainThread) litecli.main ERROR - sql: '\\v s', error: OperationalError('unrecognized token: "\\"',)
2020-06-08 19:50:14,372 (5954/MainThread) litecli.main ERROR - traceback: 'Traceback (most recent call last):\n  File "/home/bryan/.local/pipx/venvs/litecli/lib64/python3.6/site-packages/litecli/sqlexecute.py", line 121, in run\n    for result in special.execute(cur, sql):\n  File "/home/bryan/.local/pipx/venvs/litecli/lib64/python3.6/site-packages/litecli/packages/special/main.py", line 109, in execute\n    raise CommandNotFound\nlitecli.packages.special.main.CommandNotFound\n\nDuring handling of the above exception, another exception occurred:\n\nTraceback (most recent call last):\n  File "/home/bryan/.local/pipx/venvs/litecli/lib64/python3.6/site-packages/litecli/main.py", line 441, in one_iteration\n    for title, cur, headers, status in res:\n  File "/home/bryan/.local/pipx/venvs/litecli/lib64/python3.6/site-packages/litecli/sqlexecute.py", line 125, in run\n    cur.execute(sql)\nsqlite3.OperationalError: unrecognized token: "\\"\n'
2020-06-11 14:02:05,783 (6965/MainThread) litecli.main ERROR - sql: '\\h', error: OperationalError('unrecognized token: "\\"',)
2020-06-11 14:02:05,786 (6965/MainThread) litecli.main ERROR - traceback: 'Traceback (most recent call last):\n  File "/home/bryan/.local/pipx/venvs/litecli/lib64/python3.6/site-packages/litecli/sqlexecute.py", line 121, in run\n    for result in special.execute(cur, sql):\n  File "/home/bryan/.local/pipx/venvs/litecli/lib64/python3.6/site-packages/litecli/packages/special/main.py", line 109, in execute\n    raise CommandNotFound\nlitecli.packages.special.main.CommandNotFound\n\nDuring handling of the above exception, another exception occurred:\n\nTraceback (most recent call last):\n  File "/home/bryan/.local/pipx/venvs/litecli/lib64/python3.6/site-packages/litecli/main.py", line 441, in one_iteration\n    for title, cur, headers, status in res:\n  File "/home/bryan/.local/pipx/venvs/litecli/lib64/python3.6/site-packages/litecli/sqlexecute.py", line 125, in run\n    cur.execute(sql)\nsqlite3.OperationalError: unrecognized token: "\\"\n'
2020-06-14 09:46:21,820 (21826/MainThread) litecli.main ERROR - sql: '\\f cd 15', error: OperationalError('unrecognized token: "\\"',)
2020-06-14 09:46:21,823 (21826/MainThread) litecli.main ERROR - traceback: 'Traceback (most recent call last):\n  File "/home/bryan/.local/pipx/venvs/litecli/lib64/python3.6/site-packages/litecli/main.py", line 441, in one_iteration\n    for title, cur, headers, status in res:\n  File "/home/bryan/.local/pipx/venvs/litecli/lib64/python3.6/site-packages/litecli/sqlexecute.py", line 121, in run\n    for result in special.execute(cur, sql):\n  File "/home/bryan/.local/pipx/venvs/litecli/lib64/python3.6/site-packages/litecli/packages/special/iocommands.py", line 210, in execute_favorite_query\n    cur.execute(sql)\nsqlite3.OperationalError: unrecognized token: "\\"\n'
2020-06-28 14:05:22,580 (29124/MainThread) litecli.main ERROR - sql: 'wrap', error: OperationalError('near "wrap": syntax error',)
2020-06-28 14:05:22,583 (29124/MainThread) litecli.main ERROR - traceback: 'Traceback (most recent call last):\n  File "/home/bryan/.local/pipx/venvs/litecli/lib64/python3.6/site-packages/litecli/sqlexecute.py", line 121, in run\n    for result in special.execute(cur, sql):\n  File "/home/bryan/.local/pipx/venvs/litecli/lib64/python3.6/site-packages/litecli/packages/special/main.py", line 109, in execute\n    raise CommandNotFound\nlitecli.packages.special.main.CommandNotFound\n\nDuring handling of the above exception, another exception occurred:\n\nTraceback (most recent call last):\n  File "/home/bryan/.local/pipx/venvs/litecli/lib64/python3.6/site-packages/litecli/main.py", line 441, in one_iteration\n    for title, cur, headers, status in res:\n  File "/home/bryan/.local/pipx/venvs/litecli/lib64/python3.6/site-packages/litecli/sqlexecute.py", line 125, in run\n    cur.execute(sql)\nsqlite3.OperationalError: near "wrap": syntax error\n'
2020-06-28 14:05:27,289 (29124/MainThread) litecli.main ERROR - sql: 'll', error: OperationalError('near "ll": syntax error',)
2020-06-28 14:05:27,289 (29124/MainThread) litecli.main ERROR - traceback: 'Traceback (most recent call last):\n  File "/home/bryan/.local/pipx/venvs/litecli/lib64/python3.6/site-packages/litecli/sqlexecute.py", line 121, in run\n    for result in special.execute(cur, sql):\n  File "/home/bryan/.local/pipx/venvs/litecli/lib64/python3.6/site-packages/litecli/packages/special/main.py", line 109, in execute\n    raise CommandNotFound\nlitecli.packages.special.main.CommandNotFound\n\nDuring handling of the above exception, another exception occurred:\n\nTraceback (most recent call last):\n  File "/home/bryan/.local/pipx/venvs/litecli/lib64/python3.6/site-packages/litecli/main.py", line 441, in one_iteration\n    for title, cur, headers, status in res:\n  File "/home/bryan/.local/pipx/venvs/litecli/lib64/python3.6/site-packages/litecli/sqlexecute.py", line 125, in run\n    cur.execute(sql)\nsqlite3.OperationalError: near "ll": syntax error\n'
2020-06-28 14:08:29,734 (29124/MainThread) litecli.main ERROR - sql: 'q', error: OperationalError('near "q": syntax error',)
2020-06-28 14:08:29,734 (29124/MainThread) litecli.main ERROR - traceback: 'Traceback (most recent call last):\n  File "/home/bryan/.local/pipx/venvs/litecli/lib64/python3.6/site-packages/litecli/sqlexecute.py", line 121, in run\n    for result in special.execute(cur, sql):\n  File "/home/bryan/.local/pipx/venvs/litecli/lib64/python3.6/site-packages/litecli/packages/special/main.py", line 109, in execute\n    raise CommandNotFound\nlitecli.packages.special.main.CommandNotFound\n\nDuring handling of the above exception, another exception occurred:\n\nTraceback (most recent call last):\n  File "/home/bryan/.local/pipx/venvs/litecli/lib64/python3.6/site-packages/litecli/main.py", line 441, in one_iteration\n    for title, cur, headers, status in res:\n  File "/home/bryan/.local/pipx/venvs/litecli/lib64/python3.6/site-packages/litecli/sqlexecute.py", line 125, in run\n    cur.execute(sql)\nsqlite3.OperationalError: near "q": syntax error\n'
2020-07-11 14:48:12,584 (18928/MainThread) litecli.main ERROR - sql: 'select title, company, create_date from jobs;', error: OperationalError('no such column: create_date',)
2020-07-11 14:48:12,587 (18928/MainThread) litecli.main ERROR - traceback: 'Traceback (most recent call last):\n  File "/home/bryan/.local/pipx/venvs/litecli/lib64/python3.6/site-packages/litecli/sqlexecute.py", line 121, in run\n    for result in special.execute(cur, sql):\n  File "/home/bryan/.local/pipx/venvs/litecli/lib64/python3.6/site-packages/litecli/packages/special/main.py", line 109, in execute\n    raise CommandNotFound\nlitecli.packages.special.main.CommandNotFound\n\nDuring handling of the above exception, another exception occurred:\n\nTraceback (most recent call last):\n  File "/home/bryan/.local/pipx/venvs/litecli/lib64/python3.6/site-packages/litecli/main.py", line 441, in one_iteration\n    for title, cur, headers, status in res:\n  File "/home/bryan/.local/pipx/venvs/litecli/lib64/python3.6/site-packages/litecli/sqlexecute.py", line 125, in run\n    cur.execute(sql)\nsqlite3.OperationalError: no such column: create_date\n'
2020-07-11 14:48:15,765 (18928/MainThread) litecli.main ERROR - sql: '\\d', error: ArgumentMissing('Table name required.',)
2020-07-11 14:48:15,767 (18928/MainThread) litecli.main ERROR - traceback: 'Traceback (most recent call last):\n  File "/home/bryan/.local/pipx/venvs/litecli/lib64/python3.6/site-packages/litecli/main.py", line 441, in one_iteration\n    for title, cur, headers, status in res:\n  File "/home/bryan/.local/pipx/venvs/litecli/lib64/python3.6/site-packages/litecli/sqlexecute.py", line 121, in run\n    for result in special.execute(cur, sql):\n  File "/home/bryan/.local/pipx/venvs/litecli/lib64/python3.6/site-packages/litecli/packages/special/main.py", line 121, in execute\n    return special_cmd.handler(cur=cur, arg=arg, verbose=verbose)\n  File "/home/bryan/.local/pipx/venvs/litecli/lib64/python3.6/site-packages/litecli/packages/special/dbcommands.py", line 191, in describe\n    raise ArgumentMissing("Table name required.")\nlitecli.packages.special.main.ArgumentMissing: Table name required.\n'
